<?xml version="1.0" encoding="utf-8"?>
<!-- This URDF was automatically created by SolidWorks to URDF Exporter! Originally created by Stephen Brawner (brawner@gmail.com) 
     Commit Version: 1.5.1-0-g916b5db  Build Version: 1.5.7152.31018
     For more information, please see http://wiki.ros.org/sw_urdf_exporter -->
<robot
  name="my_arm">
  <link
    name="base_link">
    <inertial>
      <origin
        xyz="-1.6373E-33 0.10548 -1.897E-18"
        rpy="0 0 0" />
      <mass
        value="61.792" />
      <inertia
        ixx="2.3205"
        ixy="-9.4162E-35"
        ixz="-9.03E-33"
        iyy="1.278"
        iyz="-2.2122E-16"
        izz="2.3205" />
    </inertial>
    <visual>
      <origin
        xyz="0 0 0"
        rpy="0 0 0" />
      <geometry>
        <mesh
          filename="package://my_arm/meshes/base_link.STL" />
      </geometry>
      <material
        name="">
        <color
          rgba="1 1 1 1" />
      </material>
    </visual>
    <collision>
      <origin
        xyz="0 0 0"
        rpy="0 0 0" />
      <geometry>
        <mesh
          filename="package://my_arm/meshes/base_link.STL" />
      </geometry>
    </collision>
  </link>
  <link
    name="link_1">
    <inertial>
      <origin
        xyz="0.0076622 -1.1102E-16 -1.7126E-18"
        rpy="0 0 0" />
      <mass
        value="2.8675" />
      <inertia
        ixx="0.022307"
        ixy="-2.791E-20"
        ixz="-1.4455E-19"
        iyy="0.045723"
        iyz="2.3605E-35"
        izz="0.023846" />
    </inertial>
    <visual>
      <origin
        xyz="0 0 0"
        rpy="0 0 0" />
      <geometry>
        <mesh
          filename="package://my_arm/meshes/link_1.STL" />
      </geometry>
      <material
        name="">
        <color
          rgba="1 1 1 1" />
      </material>
    </visual>
    <collision>
      <origin
        xyz="0 0 0"
        rpy="0 0 0" />
      <geometry>
        <mesh
          filename="package://my_arm/meshes/link_1.STL" />
      </geometry>
    </collision>
  </link>
  <joint
    name="joint_1"
    type="prismatic">
    <origin
      xyz="-0.0049087 0.645 0"
      rpy="0 0 0" />
    <parent
      link="base_link" />
    <child
      link="link_1" />
    <axis
      xyz="0 1 0" />
    <limit
      lower="-0.2"
      upper="0.2"
      effort="0"
      velocity="0" />
  </joint>
  <link
    name="link_2">
    <inertial>
      <origin
        xyz="0.129549296585514 -1.11022302462516E-16 5.92442601644316E-18"
        rpy="0 0 0" />
      <mass
        value="0.237205750411731" />
      <inertia
        ixx="3.51832547415397E-05"
        ixy="1.32137843238698E-20"
        ixz="-1.38141671631462E-21"
        iyy="0.00139354606067047"
        iyz="8.47032947254301E-22"
        izz="0.00139314845285025" />
    </inertial>
    <visual>
      <origin
        xyz="0 0 0"
        rpy="0 0 0" />
      <geometry>
        <mesh
          filename="package://my_arm/meshes/link_2.STL" />
      </geometry>
      <material
        name="">
        <color
          rgba="1 1 1 1" />
      </material>
    </visual>
    <collision>
      <origin
        xyz="0 0 0"
        rpy="0 0 0" />
      <geometry>
        <mesh
          filename="package://my_arm/meshes/link_2.STL" />
      </geometry>
    </collision>
  </link>
  <joint
    name="joint_2"
    type="revolute">
    <origin
      xyz="0.20286 0 0"
      rpy="0 0 0" />
    <parent
      link="link_1" />
    <child
      link="link_2" />
    <axis
      xyz="0 0 -1" />
    <limit
      lower="-2.96"
      upper="2.96"
      effort="0"
      velocity="0" />
  </joint>
  <link
    name="link_3">
    <inertial>
      <origin
        xyz="0.110437195551162 -3.03292391201637E-09 3.02405518343957E-09"
        rpy="0 0 0" />
      <mass
        value="0.202807656870117" />
      <inertia
        ixx="3.00310414455542E-05"
        ixy="6.37839862086387E-11"
        ixz="-7.74984844037195E-11"
        iyy="0.00087548730391964"
        iyz="2.17857153122399E-10"
        izz="0.000875225249912357" />
    </inertial>
    <visual>
      <origin
        xyz="0 0 0"
        rpy="0 0 0" />
      <geometry>
        <mesh
          filename="package://my_arm/meshes/link_3.STL" />
      </geometry>
      <material
        name="">
        <color
          rgba="1 1 1 1" />
      </material>
    </visual>
    <collision>
      <origin
        xyz="0 0 0"
        rpy="0 0 0" />
      <geometry>
        <mesh
          filename="package://my_arm/meshes/link_3.STL" />
      </geometry>
    </collision>
  </link>
  <joint
    name="joint_3"
    type="revolute">
    <origin
      xyz="0.24 0 0"
      rpy="0 0 0" />
    <parent
      link="link_2" />
    <child
      link="link_3" />
    <axis
      xyz="0 0 1" />
    <limit
      lower="-2.96"
      upper="2.96"
      effort="0"
      velocity="0" />
  </joint>
  <link
    name="link_4">
    <inertial>
      <origin
        xyz="0 0 -9.54168519270915E-20"
        rpy="0 0 0" />
      <mass
        value="0.0353429173528852" />
      <inertia
        ixx="3.97607820219959E-06"
        ixy="3.52930394689292E-22"
        ixz="-4.41162993361615E-23"
        iyy="9.35114688295089E-06"
        iyz="5.23881054616918E-23"
        izz="9.35114688295089E-06" />
    </inertial>
    <visual>
      <origin
        xyz="0 0 0"
        rpy="0 0 0" />
      <geometry>
        <mesh
          filename="package://my_arm/meshes/link_4.STL" />
      </geometry>
      <material
        name="">
        <color
          rgba="1 1 1 1" />
      </material>
    </visual>
    <collision>
      <origin
        xyz="0 0 0"
        rpy="0 0 0" />
      <geometry>
        <mesh
          filename="package://my_arm/meshes/link_4.STL" />
      </geometry>
    </collision>
  </link>
  <joint
    name="joint_4"
    type="revolute">
    <origin
      xyz="0.24955 0 0"
      rpy="0 0 0" />
    <parent
      link="link_3" />
    <child
      link="link_4" />
    <axis
      xyz="1 0 0" />
    <limit
      lower="-2.96"
      upper="2.96"
      effort="0"
      velocity="0" />
  </joint>
  <link
    name="link_hand">
    <inertial>
      <origin
        xyz="-0.04 0 -0.00025263"
        rpy="0 0 0" />
      <mass
        value="0.08" />
      <inertia
        ixx="0.00012533"
        ixy="1.0538E-20"
        ixz="3.0316E-07"
        iyy="0.00014133"
        iyz="-1.7433E-20"
        izz="3.7333E-05" />
    </inertial>
    <visual>
      <origin
        xyz="0 0 0"
        rpy="0 0 0" />
      <geometry>
        <mesh
          filename="package://my_arm/meshes/link_hand.STL" />
      </geometry>
      <material
        name="">
        <color
          rgba="1 1 1 1" />
      </material>
    </visual>
    <collision>
      <origin
        xyz="0 0 0"
        rpy="0 0 0" />
      <geometry>
        <mesh
          filename="package://my_arm/meshes/link_hand.STL" />
      </geometry>
    </collision>
  </link>
  <joint
    name="joint_hand"
    type="fixed">
    <origin
      xyz="0.085 0 0"
      rpy="0 0 0" />
    <parent
      link="link_4" />
    <child
      link="link_hand" />
    <axis
      xyz="0 0 0" />
  </joint>
</robot>